{"trial_id": "0000", "hyperparameters": {"space": [{"class_name": "Choice", "config": {"name": "activation", "default": "relu", "conditions": [], "values": ["relu", "tanh"], "ordered": false}}, {"class_name": "Int", "config": {"name": "layer_1", "default": null, "conditions": [], "min_value": 1, "max_value": 1000, "step": 100, "sampling": "linear"}}, {"class_name": "Int", "config": {"name": "layer_2", "default": null, "conditions": [], "min_value": 1, "max_value": 1000, "step": 100, "sampling": "linear"}}, {"class_name": "Choice", "config": {"name": "learning_rate", "default": 0.01, "conditions": [], "values": [0.01, 0.001, 0.0001], "ordered": true}}], "values": {"activation": "tanh", "layer_1": 601, "layer_2": 701, "learning_rate": 0.01, "tuner/epochs": 2, "tuner/initial_epoch": 0, "tuner/bracket": 2, "tuner/round": 0}}, "metrics": {"metrics": {}}, "score": null, "best_step": 0, "status": "FAILED", "message": "Traceback (most recent call last):\n  File \"/Users/rem76/miniconda3/envs/GISP_init/lib/python3.10/site-packages/keras_tuner/src/engine/base_tuner.py\", line 273, in _try_run_and_update_trial\n    self._run_and_update_trial(trial, *fit_args, **fit_kwargs)\n  File \"/Users/rem76/miniconda3/envs/GISP_init/lib/python3.10/site-packages/keras_tuner/src/engine/base_tuner.py\", line 238, in _run_and_update_trial\n    results = self.run_trial(trial, *fit_args, **fit_kwargs)\n  File \"/Users/rem76/miniconda3/envs/GISP_init/lib/python3.10/site-packages/keras_tuner/src/tuners/hyperband.py\", line 427, in run_trial\n    return super().run_trial(trial, *fit_args, **fit_kwargs)\n  File \"/Users/rem76/miniconda3/envs/GISP_init/lib/python3.10/site-packages/keras_tuner/src/engine/tuner.py\", line 314, in run_trial\n    obj_value = self._build_and_fit_model(trial, *args, **copied_kwargs)\n  File \"/Users/rem76/miniconda3/envs/GISP_init/lib/python3.10/site-packages/keras_tuner/src/engine/tuner.py\", line 233, in _build_and_fit_model\n    results = self.hypermodel.fit(hp, model, *args, **kwargs)\n  File \"/Users/rem76/miniconda3/envs/GISP_init/lib/python3.10/site-packages/keras_tuner/src/engine/hypermodel.py\", line 149, in fit\n    return model.fit(*args, **kwargs)\n  File \"/Users/rem76/miniconda3/envs/GISP_init/lib/python3.10/site-packages/keras/src/utils/traceback_utils.py\", line 70, in error_handler\n    raise e.with_traceback(filtered_tb) from None\n  File \"/Users/rem76/miniconda3/envs/GISP_init/lib/python3.10/site-packages/tensorflow/python/eager/execute.py\", line 60, in quick_execute\n    tensors = pywrap_tfe.TFE_Py_Execute(ctx._handle, device_name, op_name,\ntensorflow.python.framework.errors_impl.InvalidArgumentError: Graph execution error:\n\nDetected at node sparse_categorical_crossentropy/SparseSoftmaxCrossEntropyWithLogits/SparseSoftmaxCrossEntropyWithLogits defined at (most recent call last):\n  File \"/Users/rem76/miniconda3/envs/GISP_init/lib/python3.10/runpy.py\", line 196, in _run_module_as_main\n\n  File \"/Users/rem76/miniconda3/envs/GISP_init/lib/python3.10/runpy.py\", line 86, in _run_code\n\n  File \"/Users/rem76/miniconda3/envs/GISP_init/lib/python3.10/site-packages/ipykernel_launcher.py\", line 17, in <module>\n\n  File \"/Users/rem76/miniconda3/envs/GISP_init/lib/python3.10/site-packages/traitlets/config/application.py\", line 1041, in launch_instance\n\n  File \"/Users/rem76/miniconda3/envs/GISP_init/lib/python3.10/site-packages/ipykernel/kernelapp.py\", line 724, in start\n\n  File \"/Users/rem76/miniconda3/envs/GISP_init/lib/python3.10/site-packages/tornado/platform/asyncio.py\", line 215, in start\n\n  File \"/Users/rem76/miniconda3/envs/GISP_init/lib/python3.10/asyncio/base_events.py\", line 603, in run_forever\n\n  File \"/Users/rem76/miniconda3/envs/GISP_init/lib/python3.10/asyncio/base_events.py\", line 1906, in _run_once\n\n  File \"/Users/rem76/miniconda3/envs/GISP_init/lib/python3.10/asyncio/events.py\", line 80, in _run\n\n  File \"/Users/rem76/miniconda3/envs/GISP_init/lib/python3.10/site-packages/ipykernel/kernelbase.py\", line 512, in dispatch_queue\n\n  File \"/Users/rem76/miniconda3/envs/GISP_init/lib/python3.10/site-packages/ipykernel/kernelbase.py\", line 501, in process_one\n\n  File \"/Users/rem76/miniconda3/envs/GISP_init/lib/python3.10/site-packages/ipykernel/kernelbase.py\", line 408, in dispatch_shell\n\n  File \"/Users/rem76/miniconda3/envs/GISP_init/lib/python3.10/site-packages/ipykernel/kernelbase.py\", line 731, in execute_request\n\n  File \"/Users/rem76/miniconda3/envs/GISP_init/lib/python3.10/site-packages/ipykernel/ipkernel.py\", line 417, in do_execute\n\n  File \"/Users/rem76/miniconda3/envs/GISP_init/lib/python3.10/site-packages/ipykernel/zmqshell.py\", line 540, in run_cell\n\n  File \"/Users/rem76/miniconda3/envs/GISP_init/lib/python3.10/site-packages/IPython/core/interactiveshell.py\", line 2945, in run_cell\n\n  File \"/Users/rem76/miniconda3/envs/GISP_init/lib/python3.10/site-packages/IPython/core/interactiveshell.py\", line 3000, in _run_cell\n\n  File \"/Users/rem76/miniconda3/envs/GISP_init/lib/python3.10/site-packages/IPython/core/async_helpers.py\", line 129, in _pseudo_sync_runner\n\n  File \"/Users/rem76/miniconda3/envs/GISP_init/lib/python3.10/site-packages/IPython/core/interactiveshell.py\", line 3203, in run_cell_async\n\n  File \"/Users/rem76/miniconda3/envs/GISP_init/lib/python3.10/site-packages/IPython/core/interactiveshell.py\", line 3382, in run_ast_nodes\n\n  File \"/Users/rem76/miniconda3/envs/GISP_init/lib/python3.10/site-packages/IPython/core/interactiveshell.py\", line 3442, in run_code\n\n  File \"/var/folders/d4/chxwf4hs5kq7ttsp56s64z65mjk3qj/T/ipykernel_23758/1751720158.py\", line 61, in <module>\n\n  File \"/Users/rem76/miniconda3/envs/GISP_init/lib/python3.10/site-packages/keras_tuner/src/engine/base_tuner.py\", line 233, in search\n\n  File \"/Users/rem76/miniconda3/envs/GISP_init/lib/python3.10/site-packages/keras_tuner/src/engine/base_tuner.py\", line 273, in _try_run_and_update_trial\n\n  File \"/Users/rem76/miniconda3/envs/GISP_init/lib/python3.10/site-packages/keras_tuner/src/engine/base_tuner.py\", line 238, in _run_and_update_trial\n\n  File \"/Users/rem76/miniconda3/envs/GISP_init/lib/python3.10/site-packages/keras_tuner/src/tuners/hyperband.py\", line 427, in run_trial\n\n  File \"/Users/rem76/miniconda3/envs/GISP_init/lib/python3.10/site-packages/keras_tuner/src/engine/tuner.py\", line 314, in run_trial\n\n  File \"/Users/rem76/miniconda3/envs/GISP_init/lib/python3.10/site-packages/keras_tuner/src/engine/tuner.py\", line 233, in _build_and_fit_model\n\n  File \"/Users/rem76/miniconda3/envs/GISP_init/lib/python3.10/site-packages/keras_tuner/src/engine/hypermodel.py\", line 149, in fit\n\n  File \"/Users/rem76/miniconda3/envs/GISP_init/lib/python3.10/site-packages/keras/src/utils/traceback_utils.py\", line 65, in error_handler\n\n  File \"/Users/rem76/miniconda3/envs/GISP_init/lib/python3.10/site-packages/keras/src/engine/training.py\", line 1783, in fit\n\n  File \"/Users/rem76/miniconda3/envs/GISP_init/lib/python3.10/site-packages/keras/src/engine/training.py\", line 1377, in train_function\n\n  File \"/Users/rem76/miniconda3/envs/GISP_init/lib/python3.10/site-packages/keras/src/engine/training.py\", line 1360, in step_function\n\n  File \"/Users/rem76/miniconda3/envs/GISP_init/lib/python3.10/site-packages/keras/src/engine/training.py\", line 1349, in run_step\n\n  File \"/Users/rem76/miniconda3/envs/GISP_init/lib/python3.10/site-packages/keras/src/engine/training.py\", line 1127, in train_step\n\n  File \"/Users/rem76/miniconda3/envs/GISP_init/lib/python3.10/site-packages/keras/src/engine/training.py\", line 1185, in compute_loss\n\n  File \"/Users/rem76/miniconda3/envs/GISP_init/lib/python3.10/site-packages/keras/src/engine/compile_utils.py\", line 277, in __call__\n\n  File \"/Users/rem76/miniconda3/envs/GISP_init/lib/python3.10/site-packages/keras/src/losses.py\", line 143, in __call__\n\n  File \"/Users/rem76/miniconda3/envs/GISP_init/lib/python3.10/site-packages/keras/src/losses.py\", line 270, in call\n\n  File \"/Users/rem76/miniconda3/envs/GISP_init/lib/python3.10/site-packages/keras/src/losses.py\", line 2454, in sparse_categorical_crossentropy\n\n  File \"/Users/rem76/miniconda3/envs/GISP_init/lib/python3.10/site-packages/keras/src/backend.py\", line 5777, in sparse_categorical_crossentropy\n\nReceived a label value of 1 which is outside the valid range of [0, 1).  Label values: 1 0 0 1 0 0 0 1 1 1 1 0 1 1 0 0 0 0 1 0 0 0 0 1 1 1 1 1 0 0 1 0\n\t [[{{node sparse_categorical_crossentropy/SparseSoftmaxCrossEntropyWithLogits/SparseSoftmaxCrossEntropyWithLogits}}]] [Op:__inference_train_function_1095]\n"}